Workbook

Sheet Painel
B2: COBERTURA DE CÂMERAS NOS LOCAIS DE VOTAÇÃO
B3: Municípios do programa VPE — Estado da Bahia | Raio de referência: 100 metros
B5: INDICADORES GERAIS
C6: Locais analisados | D6: Locais COM câmera ≤ 100 m | E6: Locais SEM câmera ≤ 100 m | F6: Cobertura
C7: =COUNTA('Resumo por Local'!$A$4:$A$3030) -> 3027 | D7: =COUNTIF('Resumo por Local'!$I$4:$I$3030,"SIM") -> 348 | E7: =COUNTIF('Resumo por Local'!$I$4:$I$3030,"NÃO") -> 2679 | F7: =D7/C7 -> 0.11496531
C9: Seções eleitorais no total | D9: Seções em locais cobertos | E9: % de seções cobertas | F9: Municípios | G9: Zonas eleitorais
C10: =SUM('Resumo por Local'!$H$4:$H$3030) -> 17872 | D10: =SUMIF('Resumo por Local'!$I$4:$I$3030,"SIM",'Resumo por Local'!$H$4:$H$3030) -> 3263 | E10: =D10/C10 -> 0.1825761 | F10: =SUM('Resumo por Local'!$S$4:$S$3030) -> 77 | G10: =SUM('Resumo por Local'!$T$4:$T$3030) -> 97
B12: LOCAIS ATENDIDOS POR RAIO DE DISTÂNCIA
B13: Raio | C13: Locais atendidos | D13: % do total | E13: Locais não atendidos
B14: Até 50 m | C14: =COUNTIF('Resumo por Local'!$L$4:$L$3030,">0") -> 148 | D14: =C14/$C$7 -> 0.048893294 | E14: =$C$7-C14 -> 2879
B15: Até 100 m (referência) | C15: =COUNTIF('Resumo por Local'!$M$4:$M$3030,">0") -> 348 | D15: =C15/$C$7 -> 0.11496531 | E15: =$C$7-C15 -> 2679
B16: Até 200 m | C16: =COUNTIF('Resumo por Local'!$N$4:$N$3030,">0") -> 774 | D16: =C16/$C$7 -> 0.25569871 | E16: =$C$7-C16 -> 2253
B17: Até 300 m | C17: =COUNTIF('Resumo por Local'!$O$4:$O$3030,">0") -> 1084 | D17: =C17/$C$7 -> 0.35811034 | E17: =$C$7-C17 -> 1943
B19: DISTRIBUIÇÃO DOS LOCAIS PELA CÂMERA MAIS PRÓXIMA
B20: Faixa de distância | C20: Locais | D20: % do total
B21: 1. Até 50 m | C21: =COUNTIF('Resumo por Local'!$K$4:$K$3030,"1. Até 50 m") -> 148 | D21: =C21/$C$7 -> 0.048893294
B22: 2. De 50 a 100 m | C22: =COUNTIF('Resumo por Local'!$K$4:$K$3030,"2. De 50 a 100 m") -> 200 | D22: =C22/$C$7 -> 0.066072019
B23: 3. De 100 a 200 m | C23: =COUNTIF('Resumo por Local'!$K$4:$K$3030,"3. De 100 a 200 m") -> 426 | D23: =C23/$C$7 -> 0.1407334
B24: 4. De 200 a 300 m | C24: =COUNTIF('Resumo por Local'!$K$4:$K$3030,"4. De 200 a 300 m") -> 313 | D24: =C24/$C$7 -> 0.10340271
B25: 5. De 300 a 500 m | C25: =COUNTIF('Resumo por Local'!$K$4:$K$3030,"5. De 300 a 500 m") -> 402 | D25: =C25/$C$7 -> 0.13280476
B26: 6. De 500 m a 2 km | C26: =COUNTIF('Resumo por Local'!$K$4:$K$3030,"6. De 500 m a 2 km") -> 431 | D26: =C26/$C$7 -> 0.1423852
B27: 7. Acima de 2 km | C27: =COUNTIF('Resumo por Local'!$K$4:$K$3030,"7. Acima de 2 km") -> 1107 | D27: =C27/$C$7 -> 0.36570862
B28: TOTAL | C28: =SUM(C21:C27) -> 3027 | D28: =SUM(D21:D27) -> 1
B30: 12 MUNICÍPIOS COM MAIS LOCAIS SEM CÂMERA EM 100 m
B31: Município | C31: Locais sem câmera | D31: Locais com câmera | E31: Total de locais | F31: Cobertura
B32: SALVADOR | C32: =COUNTIFS('Resumo por Local'!$A$4:$A$3030,$B32,'Resumo por Local'!$I$4:$I$3030,"NÃO") -> 290 | D32: =COUNTIFS('Resumo por Local'!$A$4:$A$3030,$B32,'Resumo por Local'!$I$4:$I$3030,"SIM") -> 126 | E32: =COUNTIF('Resumo por Local'!$A$4:$A$3030,$B32) -> 416 | F32: =IF(E32=0,"",D32/E32) -> 0.30288462
B33: FEIRA DE SANTANA | C33: =COUNTIFS('Resumo por Local'!$A$4:$A$3030,$B33,'Resumo por Local'!$I$4:$I$3030,"NÃO") -> 125 | D33: =COUNTIFS('Resumo por Local'!$A$4:$A$3030,$B33,'Resumo por Local'!$I$4:$I$3030,"SIM") -> 18 | E33: =COUNTIF('Resumo por Local'!$A$4:$A$3030,$B33) -> 143 | F33: =IF(E33=0,"",D33/E33) -> 0.12587413
B34: VITÓRIA DA CONQUISTA | C34: =COUNTIFS('Resumo por Local'!$A$4:$A$3030,$B34,'Resumo por Local'!$I$4:$I$3030,"NÃO") -> 125 | D34: =COUNTIFS('Resumo por Local'!$A$4:$A$3030,$B34,'Resumo por Local'!$I$4:$I$3030,"SIM") -> 14 | E34: =COUNTIF('Resumo por Local'!$A$4:$A$3030,$B34) -> 139 | F34: =IF(E34=0,"",D34/E34) -> 0.10071942
B35: JUAZEIRO | C35: =COUNTIFS('Resumo por Local'!$A$4:$A$3030,$B35,'Resumo por Local'!$I$4:$I$3030,"NÃO") -> 100 | D35: =COUNTIFS('Resumo por Local'!$A$4:$A$3030,$B35,'Resumo por Local'!$I$4:$I$3030,"SIM") -> 13 | E35: =COUNTIF('Resumo por Local'!$A$4:$A$3030,$B35) -> 113 | F35: =IF(E35=0,"",D35/E35) -> 0.11504425
B36: CASA NOVA | C36: =COUNTIFS('Resumo por Local'!$A$4:$A$3030,$B36,'Resumo por Local'!$I$4:$I$3030,"NÃO") -> 78 | D36: =COUNTIFS('Resumo por Local'!$A$4:$A$3030,$B36,'Resumo por Local'!$I$4:$I$3030,"SIM") -> 3 | E36: =COUNTIF('Resumo por Local'!$A$4:$A$3030,$B36) -> 81 | F36: =IF(E36=0,"",D36/E36) -> 0.037037037
B37: JEQUIÉ | C37: =COUNTIFS('Resumo por Local'!$A$4:$A$3030,$B37,'Resumo por Local'!$I$4:$I$3030,"NÃO") -> 78 | D37: =COUNTIFS('Resumo por Local'!$A$4:$A$3030,$B37,'Resumo por Local'!$I$4:$I$3030,"SIM") -> 1 | E37: =COUNTIF('Resumo por Local'!$A$4:$A$3030,$B37) -> 79 | F37: =IF(E37=0,"",D37/E37) -> 0.012658228
B38: BARREIRAS | C38: =COUNTIFS('Resumo por Local'!$A$4:$A$3030,$B38,'Resumo por Local'!$I$4:$I$3030,"NÃO") -> 68 | D38: =COUNTIFS('Resumo por Local'!$A$4:$A$3030,$B38,'Resumo por Local'!$I$4:$I$3030,"SIM") -> 6 | E38: =COUNTIF('Resumo por Local'!$A$4:$A$3030,$B38) -> 74 | F38: =IF(E38=0,"",D38/E38) -> 0.081081081
B39: SERRINHA | C39: =COUNTIFS('Resumo por Local'!$A$4:$A$3030,$B39,'Resumo por Local'!$I$4:$I$3030,"NÃO") -> 67 | D39: =COUNTIFS('Resumo por Local'!$A$4:$A$3030,$B39,'Resumo por Local'!$I$4:$I$3030,"SIM") -> 0 | E39: =COUNTIF('Resumo por Local'!$A$4:$A$3030,$B39) -> 67 | F39: =IF(E39=0,"",D39/E39) -> 0
B40: SEABRA | C40: =COUNTIFS('Resumo por Local'!$A$4:$A$3030,$B40,'Resumo por Local'!$I$4:$I$3030,"NÃO") -> 66 | D40: =COUNTIFS('Resumo por Local'!$A$4:$A$3030,$B40,'Resumo por Local'!$I$4:$I$3030,"SIM") -> 0 | E40: =COUNTIF('Resumo por Local'!$A$4:$A$3030,$B40) -> 66 | F40: =IF(E40=0,"",D40/E40) -> 0
B41: CAMAÇARI | C41: =COUNTIFS('Resumo por Local'!$A$4:$A$3030,$B41,'Resumo por Local'!$I$4:$I$3030,"NÃO") -> 62 | D41: =COUNTIFS('Resumo por Local'!$A$4:$A$3030,$B41,'Resumo por Local'!$I$4:$I$3030,"SIM") -> 8 | E41: =COUNTIF('Resumo por Local'!$A$4:$A$3030,$B41) -> 70 | F41: =IF(E41=0,"",D41/E41) -> 0.11428571
B42: PAULO AFONSO | C42: =COUNTIFS('Resumo por Local'!$A$4:$A$3030,$B42,'Resumo por Local'!$I$4:$I$3030,"NÃO") -> 60 | D42: =COUNTIFS('Resumo por Local'!$A$4:$A$3030,$B42,'Resumo por Local'!$I$4:$I$3030,"SIM") -> 1 | E42: =COUNTIF('Resumo por Local'!$A$4:$A$3030,$B42) -> 61 | F42: =IF(E42=0,"",D42/E42) -> 0.016393443
B43: CAETITÉ | C43: =COUNTIFS('Resumo por Local'!$A$4:$A$3030,$B43,'Resumo por Local'!$I$4:$I$3030,"NÃO") -> 57 | D43: =COUNTIFS('Resumo por Local'!$A$4:$A$3030,$B43,'Resumo por Local'!$I$4:$I$3030,"SIM") -> 0 | E43: =COUNTIF('Resumo por Local'!$A$4:$A$3030,$B43) -> 57 | F43: =IF(E43=0,"",D43/E43) -> 0
B45: NOTAS METODOLÓGICAS
B46: • Fonte: planilha "cameras_100m_locais_votacao_VPE.xlsx", aba "resumo_por_local". Esta planilha reorganiza os mesmos dados, sem alterá-los.
B47: • Base de câmeras de 16/09/2026 e base de locais de votação de 09/07/2026. Distâncias por fórmula de Haversine (WGS84, R = 6.371.008,8 m).
...

Sheet Resumo por Local
A1: LOCAIS DE VOTAÇÃO E COBERTURA DE CÂMERAS — MUNICÍPIOS VPE / BAHIA
A2: Critério: proximidade geodésica (Haversine/WGS84). Câmeras: 16/09/2026 · Locais: 09/07/2026. Use os filtros do cabeçalho para navegar. As colunas de coordenadas e junta eleitoral estão recolhidas no botão [+] acima.
A3: Município | B3: Zona Eleitoral | C3: Nº do Local | D3: Nome do Local de Votação | E3: Bairro | F3: Endereço | G3: CEP | H3: Seções | I3: Câmera em até 100 m | J3: Distância da câmera mais próxima (m) | K3: Faixa de distância | L3: Câmeras até 50 m | M3: Câmeras até 100 m | N3: Câmeras até 200 m | O3: Câmeras até 300 m | P3: Latitude | Q3: Longitude | R3: Endereço da Junta Eleitoral | S3: aux_municipio | T3: aux_zona
A4: ALAGOINHAS | B4: 163 | C4: 1015 | D4: COLÉGIO MARIA DE LOURDES | E4: RIACHO DA GUIA | F4: RUA MANOEL LUIZ CARVALHO - ZONA RURAL | G4: 48105-000 | H4: 5 | I4: NÃO | K4: =IF(J4="","7. Acima de 2 km",IF(J4<=50,"1. Até 50 m",IF(J4<=100,"2. De 50 a 100 m",IF(J4<=200,"3. De 100 a 200 m",IF(J4<=300,"4. De 200 a 300 m",IF(J4<=500,"5. De 300 a 500 m","6. De 500 m a 2 km")))))) -> 7. Acima de 2 km | L4: 0 | M4: 0 | N4: 0 | O4: 0 | P4: -11.956991 | Q4: -38.378609 | R4: FÓRUM DES. MOACYR PITTA LIMA, AVENIDA AIRTON SENNA, S/N, ALAGOINHAS VELHA, ALAGOINHAS/BA | S4: =IF(A4=A3,0,1) -> 1 | T4: =IF(COUNTIF($B$4:B4,B4)=1,1,0) -> 1
A5: ALAGOINHAS | B5: 163 | C5: 1023 | D5: COLÉGIO JAIRO AZI | E5: RIACHO DA GUIA | F5: RUA SAGRADA FAMÍLIA, S/N - ZONA RURAL | G5: 48105-000 | H5: 10 | I5: NÃO | K5: =IF(J5="","7. Acima de 2 km",IF(J5<=50,"1. Até 50 m",IF(J5<=100,"2. De 50 a 100 m",IF(J5<=200,"3. De 100 a 200 m",IF(J5<=300,"4. De 200 a 300 m",IF(J5<=500,"5. De 300 a 500 m","6. De 500 m a 2 km")))))) -> 7. Acima de 2 km | L5: 0 | M5: 0 | N5: 0 | O5: 0 | P5: -11.958491 | Q5: -38.377551 | R5: FÓRUM DES. MOACYR PITTA LIMA, AVENIDA AIRTON SENNA, S/N, ALAGOINHAS VELHA, ALAGOINHAS/BA | S5: =IF(A5=A4,0,1) -> 0 | T5: =IF(COUNTIF($B$4:B5,B5)=1,1,0) -> 0
A6: ALAGOINHAS | B6: 163 | C6: 1090 | D6: ESCOLA MUNICIPAL D. AVELAR BRANDÃO VILELA | E6: DISTRITO BOA UNIÃO | F6: RUA DA CAPELINHA - ZONA RURAL | G6: 48103-000 | H6: 6 | I6: NÃO | K6: =IF(J6="","7. Acima de 2 km",IF(J6<=50,"1. Até 50 m",IF(J6<=100,"2. De 50 a 100 m",IF(J6<=200,"3. De 100 a 200 m",IF(J6<=300,"4. De 200 a 300 m",IF(J6<=500,"5. De 300 a 500 m","6. De 500 m a 2 km")))))) -> 7. Acima de 2 km | L6: 0 | M6: 0 | N6: 0 | O6: 0 | P6: -12.184316 | Q6: -38.504754 | R6: FÓRUM DES. MOACYR PITTA LIMA, AVENIDA AIRTON SENNA, S/N, ALAGOINHAS VELHA, ALAGOINHAS/BA | S6: =IF(A6=A5,0,1) -> 0 | T6: =IF(COUNTIF($B$4:B6,B6)=1,1,0) -> 0
A7: ALAGOINHAS | B7: 163 | C7: 1139 | D7: GINÁSIO MIGUEL FONTES | E7: DISTRITO BOA UNIÃO | F7: RUA MANOEL TEIXEIRA LEAL - ZONA RURAL | G7: 48103-000 | H7: 5 | I7: NÃO | K7: =IF(J7="","7. Acima de 2 km",IF(J7<=50,"1. Até 50 m",IF(J7<=100,"2. De 50 a 100 m",IF(J7<=200,"3. De 100 a 200 m",IF(J7<=300,"4. De 200 a 300 m",IF(J7<=500,"5. De 300 a 500 m","6. De 500 m a 2 km")))))) -> 7. Acima de 2 km | L7: 0 | M7: 0 | N7: 0 | O7: 0 | P7: -12.187157 | Q7: -38.506306 | R7: FÓRUM DES. MOACYR PITTA LIMA, AVENIDA AIRTON SENNA, S/N, ALAGOINHAS VELHA, ALAGOINHAS/BA | S7: =IF(A7=A6,0,1) -> 0 | T7: =IF(COUNTIF($B$4:B7,B7)=1,1,0) -> 0
A8: ALAGOINHAS | B8: 163 | C8: 1147 | D8: COLÉGIO ESTADUAL DEPUTADO LUIS EDUARDO MAGALHÃES | E8: BARREIRO | F8: RUA MARGEM DA LINHA - ZONA URBANA | G8: 48022-100 | H8: 10 | I8: NÃO | J8: 171.3 | K8: =IF(J8="","7. Acima de 2 km",IF(J8<=50,"1. Até 50 m",IF(J8<=100,"2. De 50 a 100 m",IF(J8<=200,"3. De 100 a 200 m",IF(J8<=300,"4. De 200 a 300 m",IF(J8<=500,"5. De 300 a 500 m","6. De 500 m a 2 km")))))) -> 3. De 100 a 200 m | L8: 0 | M8: 0 | N8: 1 | O8: 1 | P8: -12.139834 | Q8: -38.439263 | R8: FÓRUM DES. MOACYR PITTA LIMA, AVENIDA AIRTON SENNA, S/N, ALAGOINHAS VELHA, ALAGOINHAS/BA | S8: =IF(A8=A7,0,1) -> 0 | T8: =IF(COUNTIF($B$4:B8,B8)=1,1,0) -> 0
A9: ALAGOINHAS | B9: 163 | C9: 1163 | D9: COLÉGIO DA POLÍCIA MILITAR | E9: SILVA JARDIM | F9: RUA ARTHUR PEREIRA DE AZEVEDO - S/N - ZONA URBANA | G9: 48021-740 | H9: 24 | I9: NÃO | J9: 486.9 | K9: =IF(J9="","7. Acima de 2 km",IF(J9<=50,"1. Até 50 m",IF(J9<=100,"2. De 50 a 100 m",IF(J9<=200,"3. De 100 a 200 m",IF(J9<=300,"4. De 200 a 300 m",IF(J9<=500,"5. De 300 a 500 m","6. De 500 m a 2 km")))))) -> 5. De 300 a 500 m | L9: 0 | M9: 0 | N9: 0 | O9: 0 | P9: -12.139271 | Q9: -38.434335 | R9: FÓRUM DES. MOACYR PITTA LIMA, AVENIDA AIRTON SENNA, S/N, ALAGOINHAS VELHA, ALAGOINHAS/BA | S9: =IF(A9=A8,0,1) -> 0 | T9: =IF(COUNTIF($B$4:B9,B9)=1,1,0) -> 0
A10: ALAGOINHAS | B10: 163 | C10: 1210 | D10: ESCOLA MARIA JOSÉ BASTOS DA SILVA | E10: SILVA JARDIM | F10: RUA ARTHUR PEREIRA DE AZEVEDO- ZONA URBANA | G10: 48021-740 | H10: 9 | I10: NÃO | J10: 509.6 | K10: =IF(J10="","7. Acima de 2 km",IF(J10<=50,"1. Até 50 m",IF(J10<=100,"2. De 50 a 100 m",IF(J10<=200,"3. De 100 a 200 m",IF(J10<=300,"4. De 200 a 300 m",IF(J10<=500,"5. De 300 a 500 m","6. De 500 m a 2 km")))))) -> 6. De 500 m a 2 km | L10: 0 | M10: 0 | N10: 0 | O10: 0 | P10: -12.140387 | Q10: -38.435213 | R10: FÓRUM DES. MOACYR PITTA LIMA, AVENIDA AIRTON SENNA, S/N, ALAGOINHAS VELHA, ALAGOINHAS/BA | S10: =IF(A10=A9,0,1) -> 0 | T10: =IF(COUNTIF($B$4:B10,B10)=1,1,0) -> 0
A11: ALAGOINHAS | B11: 163 | C11: 1252 | D11: ESCOLA MUNICIPAL JOSÉ HONORATO | E11: MIGUEL VELHO | F11: RUA GALDÊNCIO DE SOUZA, S/N, MIGUEL VELHO - ZONA URBANA | G11: 48024-305 | H11: 4 | I11: NÃO | J11: 136.9 | K11: =IF(J11="","7. Acima de 2 km",IF(J11<=50,"1. Até 50 m",IF(J11<=100,"2. De 50 a 100 m",IF(J11<=200,"3. De 100 a 200 m",IF(J11<=300,"4. De 200 a 300 m",IF(J11<=500,"5. De 300 a 500 m","6. De 500 m a 2 km")))))) -> 3. De 100 a 200 m | L11: 0 | M11: 0 | N11: 1 | O11: 1 | P11: -12.141456 | Q11: -38.466104 | R11: FÓRUM DES. MOACYR PITTA LIMA, AVENIDA AIRTON SENNA, S/N, ALAGOINHAS VELHA, ALAGOINHAS/BA | S11: =IF(A11=A10,0,1) -> 0 | T11: =IF(COUNTIF($B$4:B11,B11)=1,1,0) -> 0
A12: ALAGOINHAS | B12: 163 | C12: 1317 | D12: ASSOCIAÇÃO SOLIDÁRIA DO QUIZAMBU | E12: RIACHO DA GUIA | F12: POVOADO QUIZAMBU - ZONA RURAL | G12: 48000-000 | H12: 2 | I12: NÃO | K12: =IF(J12="","7. Acima de 2 km",IF(J12<=50,"1. Até 50 m",IF(J12<=100,"2. De 50 a 100 m",IF(J12<=200,"3. De 100 a 200 m",IF(J12<=300,"4. De 200 a 300 m",IF(J12<=500,"5. De 300 a 500 m","6. De 500 m a 2 km")))))) -> 7. Acima de 2 km | L12: 0 | M12: 0 | N12: 0 | O12: 0 | P12: -11.938722 | Q12: -38.404857 | R12: FÓRUM DES. MOACYR PITTA LIMA, AVENIDA AIRTON SENNA, S/N, ALAGOINHAS VELHA, ALAGOINHAS/BA | S12: =IF(A12=A11,0,1) -> 0 | T12: =IF(COUNTIF($B$4:B12,B12)=1,1,0) -> 0
A13: ALAGOINHAS | B13: 163 | C13: 1325 | D13: ESCOLA MUNICIPAL PROFESSOR MARIO LAERT | E13: BARREIRO | F13: RUA DR MURILO CAVALCANTE, 372, BARREIRO | G13: 48022-025 | H13: 3 | I13: NÃO | J13: 105.2 | K13: =IF(J13="","7. Acima de 2 km",IF(J13<=50,"1. Até 50 m",IF(J13<=100,"2. De 50 a 100 m",IF(J13<=200,"3. De 100 a 200 m",IF(J13<=300,"4. De 200 a 300 m",IF(J13<=500,"5. De 300 a 500 m","6. De 500 m a 2 km")))))) -> 3. De 100 a 200 m | L13: 0 | M13: 0 | N13: 1 | O13: 1 | P13: -12.134866 | Q13: -38.435681 | R13: FÓRUM DES. MOACYR PITTA LIMA, AVENIDA AIRTON SENNA, S/N, ALAGOINHAS VELHA, ALAGOINHAS/BA | S13: =IF(A13=A12,0,1) -> 0 | T13: =IF(COUNTIF($B$4:B13,B13)=1,1,0) -> 0
A14: ALAGOINHAS | B14: 163 | C14: 1333 | D14: ESCOLA MUNICIPAL TANCREDO DE ALMEIDA NEVES | E14: BARREIRO | F14: RUA DO AVIÃO, S/N - BARREIRO, ZONA URBANA | G14: 48022-195 | H14: 6 | I14: SIM | J14: 61.9 | K14: =IF(J14="","7. Acima de 2 km",IF(J14<=50,"1. Até 50 m",IF(J14<=100,"2. De 50 a 100 m",IF(J14<=200,"3. De 100 a 200 m",IF(J14<=300,"4. De 200 a 300 m",IF(J14<=500,"5. De 300 a 500 m","6. De 500 m a 2 km")))))) -> 2. De 50 a 100 m | L14: 0 | M14: 1 | N14: 1 | O14: 1 | P14: -12.138329 | Q14: -38.439954 | R14: FÓRUM DES. MOACYR PITTA LIMA, AVENIDA AIRTON SENNA, S/N, ALAGOINHAS VELHA, ALAGOINHAS/BA | S14: =IF(A14=A13,0,1) -> 0 | T14: =IF(COUNTIF($B$4:B14,B14)=1,1,0) -> 0
A15: ALAGOINHAS | B15: 163 | C15: 1350 | D15: FACULDADE SANTO ANTONIO | E15: CATU | F15: RUA CONSELHEIRO JUNQUEIRA, S/N - ZONA URBANA | G15: 48015-020 | H15: 8 | I15: NÃO | J15: 819.5 | K15: =IF(J15="","7. Acima de 2 km",IF(J15<=50,"1. Até 50 m",IF(J15<=100,"2. De 50 a 100 m",IF(J15<=200,"3. De 100 a 200 m",IF(J15<=300,"4. De 200 a 300 m",IF(J15<=500,"5. De 300 a 500 m","6. De 500 m a 2 km")))))) -> 6. De 500 m a 2 km | L15: 0 | M15: 0 | N15: 0 | O15: 0 | P15: -12.112577 | Q15: -38.437906 | R15: FÓRUM DES. MOACYR PITTA LIMA, AVENIDA AIRTON SENNA, S/N, ALAGOINHAS VELHA, ALAGOINHAS/BA | S15: =IF(A15=A14,0,1) -> 0 | T15: =IF(COUNTIF($B$4:B15,B15)=1,1,0) -> 0
A16: ALAGOINHAS | B16: 163 | C16: 1368 | D16: ESCOLA MUNICIPAL QUILOMBOLA PROFESSOR JOÃO ANASTÁCIO | E16: DISTRITO BOA UNIÃO | F16: POVOADO CANGULA, DISTRITO DE BOA UNIÃO | G16: 48024-899 | H16: 1 | I16: NÃO | K16: =IF(J16="","7. Acima de 2 km",IF(J16<=50,"1. Até 50 m",IF(J16<=100,"2. De 50 a 100 m",IF(J16<=200,"3. De 100 a 200 m",IF(J16<=300,"4. De 200 a 300 m",IF(J16<=500,"5. De 300 a 500 m","6. De 500 m a 2 km")))))) -> 7. Acima de 2 km | L16: 0 | M16: 0 | N16: 0 | O16: 0 | P16: -12.17847 | Q16: -38.489673 | R16: FÓRUM DES. MOACYR PITTA LIMA, AVENIDA AIRTON SENNA, S/N, ALAGOINHAS VELHA, ALAGOINHAS/BA | S16: =IF(A16=A15,0,1) -> 0 | T16: =IF(COUNTIF($B$4:B16,B16)=1,1,0) -> 0
A17: ALAGOINHAS | B17: 163 | C17: 1376 | D17: COLÉGIO ESTADUAL JÚLIO LEAL DE ARAÚJO | E17: MANGALÔ | F17: AV. MARECHAL ARISTÓTELES DE SOUZA DANTAS, BAIRRO MANGALÔ- ZONA URBANA | G17: 48005-470 | H17: 2 | I17: NÃO | J17: 1229 | K17: =IF(J17="","7. Acima de 2 km",IF(J17<=50,"1. Até 50 m",IF(J17<=100,"2. De 50 a 100 m",IF(J17<=200,"3. De 100 a 200 m",IF(J17<=300,"4. De 200 a 300 m",IF(J17<=500,"5. De 300 a 500 m","6. De 500 m a 2 km")))))) -> 6. De 500 m a 2 km | L17: 0 | M17: 0 | N17: 0 | O17: 0 | P17: -12.149122 | Q17: -38.443111 | R17: FÓRUM DES. MOACYR PITTA LIMA, AVENIDA AIRTON SENNA, S/N, ALAGOINHAS VELHA, ALAGOINHAS/BA | S17: =IF(A17=A16,0,1) -> 0 | T17: =IF(COUNTIF($B$4:B17,B17)=1,1,0) -> 0
A18: ALAGOINHAS | B18: 163 | C18: 1384 | D18: ESCOLA PROFESSOR ROBERTO SANTOS | E18: 21 DE SETEMBRO | F18: RUA 21 DE SETEMBRO, S/N - BARREIRO, ZONA URBANA | G18: 48022-035 | H18: 3 | I18: NÃO | J18: 550.3 | K18: =IF(J18="","7. Acima de 2 km",IF(J18<=50,"1. Até 50 m",IF(J18<=100,"2. De 50 a 100 m",IF(J18<=200,"3. De 100 a 200 m",IF(J18<=300,"4. De 200 a 300 m",IF(J18<=500,"5. De 300 a 500 m","6. De 500 m a 2 km")))))) -> 6. De 500 m a 2 km | L18: 0 | M18: 0 | N18: 0 | O18: 0 | P18: -12.131267 | Q18: -38.439221 | R18: FÓRUM DES. MOACYR PITTA LIMA, AVENIDA AIRTON SENNA, S/N, ALAGOINHAS VELHA, ALAGOINHAS/BA | S18: =IF(A18=A17,0,1) -> 0 | T18: =IF(COUNTIF($B$4:B18,B18)=1,1,0) -> 0
A19: ALAGOINHAS | B19: 163 | C19: 1414 | D19: ESCOLA MUNICIPAL JOANA D'ARC | E19: DOIS DE JULHO | F19: PARQUE SENHOR DO BONFIM - 2 DE JULHO- ZONA URBANA | G19: 48050-000 | H19: 3 | I19: NÃO | J19: 1353 | K19: =IF(J19="","7. Acima de 2 km",IF(J19<=50,"1. Até 50 m",IF(J19<=100,"2. De 50 a 100 m",IF(J19<=200,"3. De 100 a 200 m",IF(J19<=300,"4. De 200 a 300 m",IF(J19<=500,"5. De 300 a 500 m","6. De 500 m a 2 km")))))) -> 6. De 500 m a 2 km | L19: 0 | M19: 0 | N19: 0 | O19: 0 | P19: -12.152558 | Q19: -38.430549 | R19: FÓRUM DES. MOACYR PITTA LIMA, AVENIDA AIRTON SENNA, S/N, ALAGOINHAS VELHA, ALAGOINHAS/BA | S19: =IF(A19=A18,0,1) -> 0 | T19: =IF(COUNTIF($B$4:B19,B19)=1,1,0) -> 0
A20: ALAGOINHAS | B20: 163 | C20: 1422 | D20: ESCOLA MUNICIPAL PAULO FREIRE | E20: SILVA JARDIM | F20: RUA GETÚLIO VARGAS, S/N, PARQUE VITÓRIA, ZONA URBANA | G20: 48070-040 | H20: 4 | I20: NÃO | J20: 263.4 | K20: =IF(J20="","7. Acima de 2 km",IF(J20<=50,"1. Até 50 m",IF(J20<=100,"2. De 50 a 100 m",IF(J20<=200,"3. De 100 a 200 m",IF(J20<=300,"4. De 200 a 300 m",IF(J20<=500,"5. De 300 a 500 m","6. De 500 m a 2 km")))))) -> 4. De 200 a 300 m | L20: 0 | M20: 0 | N20: 0 | O20: 1 | P20: -12.13692 | Q20: -38.433035 | R20: FÓRUM DES. MOACYR PITTA LIMA, AVENIDA AIRTON SENNA, S/N, ALAGOINHAS VELHA, ALAGOINHAS/BA | S20: =IF(A20=A19,0,1) -> 0 | T20: =IF(COUNTIF($B$4:B20,B20)=1,1,0) -> 0
A21: ALAGOINHAS | B21: 163 | C21: 1430 | D21: ESCOLA MUNICIPAL MENINO JESUS | E21: TEREZÓPOLIS | F21: RUA DOM AVELAR BRANDÃO VILELA, 498 - ZONA URBANA | G21: 48022-010 | H21: 3 | I21: NÃO | J21: 450.4 | K21: =IF(J21="","7. Acima de 2 km",IF(J21<=50,"1. Até 50 m",IF(J21<=100,"2. De 50 a 100 m",IF(J21<=200,"3. De 100 a 200 m",IF(J21<=300,"4. De 200 a 300 m",IF(J21<=500,"5. De 300 a 500 m","6. De 500 m a 2 km")))))) -> 5. De 300 a 500 m | L21: 0 | M21: 0 | N21: 0 | O21: 0 | P21: -12.131329 | Q21: -38.434401 | R21: FÓRUM DES. MOACYR PITTA LIMA, AVENIDA AIRTON SENNA, S/N, ALAGOINHAS VELHA, ALAGOINHAS/BA | S21: =IF(A21=A20,0,1) -> 0 | T21: =IF(COUNTIF($B$4:B21,B21)=1,1,0) -> 0
A22: ALAGOINHAS | B22: 163 | C22: 1457 | D22: ESCOLA MUNICIPAL GONÇALO MUNIZ | E22: DISTRITO BOA UNIÃO | F22: POVOADO PINDOBAL | G22: 48024-899 | H22: 2 | I22: NÃO | K22: =IF(J22="","7. Acima de 2 km",IF(J22<=50,"1. Até 50 m",IF(J22<=100,"2. De 50 a 100 m",IF(J22<=200,"3. De 100 a 200 m",IF(J22<=300,"4. De 200 a 300 m",IF(J22<=500,"5. De 300 a 500 m","6. De 500 m a 2 km")))))) -> 7. Acima de 2 km | L22: 0 | M22: 0 | N22: 0 | O22: 0 | P22: -12.265054 | Q22: -38.470854 | R22: FÓRUM DES. MOACYR PITTA LIMA, AVENIDA AIRTON SENNA, S/N, ALAGOINHAS VELHA, ALAGOINHAS/BA | S22: =IF(A22=A21,0,1) -> 0 | T22: =IF(COUNTIF($B$4:B22,B22)=1,1,0) -> 0
A23: ALAGOINHAS | B23: 163 | C23: 1465 | D23: ESCOLA MUNICIPAL MIGUEL CALMON - PRÉDIO 02 | E23: SANTA ISABEL | F23: RUA 1 DE JANEIRO SN - ZONA URBANA | G23: 48000-000 | H23: 3 | I23: NÃO | J23: 727.5 | K23: =IF(J23="","7. Acima de 2 km",IF(J23<=50,"1. Até 50 m",IF(J23<=100,"2. De 50 a 100 m",IF(J23<=200,"3. De 100 a 200 m",IF(J23<=300,"4. De 200 a 300 m",IF(J23<=500,"5. De 300 a 500 m","6. De 500 m a 2 km")))))) -> 6. De 500 m a 2 km | L23: 0 | M23: 0 | N23: 0 | O23: 0 | P23: -12.144975 | Q23: -38.432403 | R23: FÓRUM DES. MOACYR PITTA LIMA, AVENIDA AIRTON SENNA, S/N, ALAGOINHAS VELHA, ALAGOINHAS/BA | S23: =IF(A23=A22,0,1) -> 0 | T23: =IF(COUNTIF($B$4:B23,B23)=1,1,0) -> 0
A24: ALAGOINHAS | B24: 163 | C24: 1473 | D24: FATEC - FACULDADE DE TECNOLOGIA E CIÊNCIA DA BAHIA | E24: SANTA ISABEL | F24: RUA IZIDÓRIO CARNEIRO DOS SANTOS, 1.111, BAIRRO MANGALÔ, ZONA URBANA | G24: 48021-855 | H24: 23 | I24: NÃO | J24: 605.4 | K24: =IF(J24="","7. Acima de 2 km",IF(J24<=50,"1. Até 50 m",IF(J24<=100,"2. De 50 a 100 m",IF(J24<=200,"3. De 100 a 200 m",IF(J24<=300,"4. De 200 a 300 m",IF(J24<=500,"5. De 300 a 500 m","6. De 500 m a 2 km")))))) -> 6. De 500 m a 2 km | L24: 0 | M24: 0 | N24: 0 | O24: 0 | P24: -12.142899 | Q24: -38.436407 | R24: FÓRUM DES. MOACYR PITTA LIMA, AVENIDA AIRTON SENNA, S/N, ALAGOINHAS VELHA, ALAGOINHAS/BA | S24: =IF(A24=A23,0,1) -> 0 | T24: =IF(COUNTIF($B$4:B24,B24)=1,1,0) -> 0
A25: ALAGOINHAS | B25: 163 | C25: 1490 | D25: ESCOLA DOS RODOVIÁRIOS | E25: PIRINEL | F25: RUA ÁUREA CRAVO, 138, PIRINEL - ZONA URBANA | G25: 48012-318 | H25: 6 | I25: NÃO | J25: 690.8 | K25: =IF(J25="","7. Acima de 2 km",IF(J25<=50,"1. Até 50 m",IF(J25<=100,"2. De 50 a 100 m",IF(J25<=200,"3. De 100 a 200 m",IF(J25<=300,"4. De 200 a 300 m",IF(J25<=500,"5. De 300 a 500 m","6. De 500 m a 2 km")))))) -> 6. De 500 m a 2 km | L25: 0 | M25: 0 | N25: 0 | O25: 0 | P25: -12.127476 | Q25: -38.417688 | R25: FÓRUM DES. MOACYR PITTA LIMA, AVENIDA AIRTON SENNA, S/N, ALAGOINHAS VELHA, ALAGOINHAS/BA | S25: =IF(A25=A24,0,1) -> 0 | T25: =IF(COUNTIF($B$4:B25,B25)=1,1,0) -> 0
A26: ALAGOINHAS | B26: 163 | C26: 1503 | D26: ESCOLA MUNICIPAL JARDIM PETROLAR | E26: JARDIM PETROLAR | F26: RUA SÃO FRANCISCO DE ASSIS, S/N - ZONA URBANA | G26: 48005-492 | H26: 2 | I26: NÃO | J26: 768.2 | K26: =IF(J26="","7. Acima de 2 km",IF(J26<=50,"1. Até 50 m",IF(J26<=100,"2. De 50 a 100 m",IF(J26<=200,"3. De 100 a 200 m",IF(J26<=300,"4. De 200 a 300 m",IF(J26<=500,"5. De 300 a 500 m","6. De 500 m a 2 km")))))) -> 6. De 500 m a 2 km | L26: 0 | M26: 0 | N26: 0 | O26: 0 | P26: -12.15244 | Q26: -38.412871 | R26: FÓRUM DES. MOACYR PITTA LIMA, AVENIDA AIRTON SENNA, S/N, ALAGOINHAS VELHA, ALAGOINHAS/BA | S26: =IF(A26=A25,0,1) -> 0 | T26: =IF(COUNTIF($B$4:B26,B26)=1,1,0) -> 0
A27: ALAGOINHAS | B27: 163 | C27: 1520 | D27: ESCOLA MUNICIPAL PADRE JOSÉ DE ANCHIETA | E27: POVOADO ESTEVÃO | F27: POVOADO ESTEVÃO - ZONA RURAL | G27: 48000-000 | H27: 3 | I27: NÃO | K27: =IF(J27="","7. Acima de 2 km",IF(J27<=50,"1. Até 50 m",IF(J27<=100,"2. De 50 a 100 m",IF(J27<=200,"3. De 100 a 200 m",IF(J27<=300,"4. De 200 a 300 m",IF(J27<=500,"5. De 300 a 500 m","6. De 500 m a 2 km")))))) -> 7. Acima de 2 km | L27: 0 | M27: 0 | N27: 0 | O27: 0 | P27: -12.184458 | Q27: -38.361798 | R27: FÓRUM DES. MOACYR PITTA LIMA, AVENIDA AIRTON SENNA, S/N, ALAGOINHAS VELHA, ALAGOINHAS/BA | S27: =IF(A27=A26,0,1) -> 0 | T27: =IF(COUNTIF($B$4:B27,B27)=1,1,0) -> 0
A28: ALAGOINHAS | B28: 163 | C28: 1538 | D28: FACULDADE UNOPAR | E28: CENTRO | F28: AV. ELVIRA DA COSTA DÓREA, N 277 - CENTRO, ZONA URBANA | G28: 48000-019 | H28: 9 | I28: NÃO | J28: 250.1 | K28: =IF(J28="","7. Acima de 2 km",IF(J28<=50,"1. Até 50 m",IF(J28<=100,"2. De 50 a 100 m",IF(J28<=200,"3. De 100 a 200 m",IF(J28<=300,"4. De 200 a 300 m",IF(J28<=500,"5. De 300 a 500 m","6. De 500 m a 2 km")))))) -> 4. De 200 a 300 m | L28: 0 | M28: 0 | N28: 0 | O28: 3 | P28: -12.138468 | Q28: -38.417252 | R28: FÓRUM DES. MOACYR PITTA LIMA, AVENIDA AIRTON SENNA, S/N, ALAGOINHAS VELHA, ALAGOINHAS/BA | S28: =IF(A28=A27,0,1) -> 0 | T28: =IF(COUNTIF($B$4:B28,B28)=1,1,0) -> 0
A29: ALAGOINHAS | B29: 163 | C29: 1554 | D29: ESCOLA ESTADUAL OSCAR CORDEIRO | E29: CENTRO | F29: AVENIDA LUIZ VIANA FILHO, S/N, CENTRO - ZONA URBANA | G29: 48005-420 | H29: 5 | I29: NÃO | J29: 820.4 | K29: =IF(J29="","7. Acima de 2 km",IF(J29<=50,"1. Até 50 m",IF(J29<=100,"2. De 50 a 100 m",IF(J29<=200,"3. De 100 a 200 m",IF(J29<=300,"4. De 200 a 300 m",IF(J29<=500,"5. De 300 a 500 m","6. De 500 m a 2 km")))))) -> 6. De 500 m a 2 km | L29: 0 | M29: 0 | N29: 0 | O29: 0 | P29: -12.148029 | Q29: -38.425553 | R29: FÓRUM DES. MOACYR PITTA LIMA, AVENIDA AIRTON SENNA, S/N, ALAGOINHAS VELHA, ALAGOINHAS/BA | S29: =IF(A29=A28,0,1) -> 0 | T29: =IF(COUNTIF($B$4:B29,B29)=1,1,0) -> 0
A30: ALAGOINHAS | B30: 163 | C30: 1562 | D30: COLÉGIO SÃO FRANCISCO | E30: CENTRO | F30: AVENIDA LAURO DE FREITAS, 198, CENTRO- ZONA URBANA | G30: 48000-103 | H30: 12 | I30: NÃO | J30: 140.6 | K30: =IF(J30="","7. Acima de 2 km",IF(J30<=50,"1. Até 50 m",IF(J30<=100,"2. De 50 a 100 m",IF(J30<=200,"3. De 100 a 200 m",IF(J30<=300,"4. De 200 a 300 m",IF(J30<=500,"5. De 300 a 500 m","6. De 500 m a 2 km")))))) -> 3. De 100 a 200 m | L30: 0 | M30: 0 | N30: 2 | O30: 2 | P30: -12.137588 | Q30: -38.417929 | R30: FÓRUM DES. MOACYR PITTA LIMA, AVENIDA AIRTON SENNA, S/N, ALAGOINHAS VELHA, ALAGOINHAS/BA | S30: =IF(A30=A29,0,1) -> 0 | T30: =IF(COUNTIF($B$4:B30,B30)=1,1,0) -> 0
A31: ALAGOINHAS | B31: 163 | C31: 1570 | D31: ESCOLA MUNICIPAL ADALGIZA SANTOS (ANEXO) | E31: CENTRO | F31: RUA LUIZ VIANA, 302, CENTRO - ZONA URBANA | G31: 48005-420 | H31: 3 | I31: NÃO | J31: 341.4 | K31: =IF(J31="","7. Acima de 2 km",IF(J31<=50,"1. Até 50 m",IF(J31<=100,"2. De 50 a 100 m",IF(J31<=200,"3. De 100 a 200 m",IF(J31<=300,"4. De 200 a 300 m",IF(J31<=500,"5. De 300 a 500 m","6. De 500 m a 2 km")))))) -> 5. De 300 a 500 m | L31: 0 | M31: 0 | N31: 0 | O31: 0 | P31: -12.143342 | Q31: -38.423943 | R31: FÓRUM DES. MOACYR PITTA LIMA, AVENIDA AIRTON SENNA, S/N, ALAGOINHAS VELHA, ALAGOINHAS/BA | S31: =IF(A31=A30,0,1) -> 0 | T31: =IF(COUNTIF($B$4:B31,B31)=1,1,0) -> 0
A32: ALAGOINHAS | B32: 163 | C32: 1589 | D32: ESCOLA VISCONDE DO RIO BRANCO | E32: POVOADO RIO BRANCO | F32: POVOADO RIO BRANCO - ZONA RURAL | G32: 48024-899 | H32: 2 | I32: NÃO | K32: =IF(J32="","7. Acima de 2 km",IF(J32<=50,"1. Até 50 m",IF(J32<=100,"2. De 50 a 100 m",IF(J32<=200,"3. De 100 a 200 m",IF(J32<=300,"4. De 200 a 300 m",IF(J32<=500,"5. De 300 a 500 m","6. De 500 m a 2 km")))))) -> 7. Acima de 2 km | L32: 0 | M32: 0 | N32: 0 | O32: 0 | P32: -12.098942 | Q32: -38.285706 | R32: FÓRUM DES. MOACYR PITTA LIMA, AVENIDA AIRTON SENNA, S/N, ALAGOINHAS VELHA, ALAGOINHAS/BA | S32: =IF(A32=A31,0,1) -> 0 | T32: =IF(COUNTIF($B$4:B32,B32)=1,1,0) -> 0
A33: ALAGOINHAS | B33: 163 | C33: 1597 | D33: ESCOLA MUNICIPAL IRENE ANDRADE DE ASSIS | E33: CENTRO | F33: RUA JOSE BATISTA DE LIRO SOBRINHO, S/N , ALAGOINHAS VELHA- ZONA URBANA | G33: 48007-526 | H33: 5 | I33: NÃO | J33: 163 | K33: =IF(J33="","7. Acima de 2 km",IF(J33<=50,"1. Até 50 m",IF(J33<=100,"2. De 50 a 100 m",IF(J33<=200,"3. De 100 a 200 m",IF(J33<=300,"4. De 200 a 300 m",IF(J33<=500,"5. De 300 a 500 m","6. De 500 m a 2 km")))))) -> 3. De 100 a 200 m | L33: 0 | M33: 0 | N33: 1 | O33: 2 | P33: -12.139998 | Q33: -38.412369 | R33: FÓRUM DES. MOACYR PITTA LIMA, AVENIDA AIRTON SENNA, S/N, ALAGOINHAS VELHA, ALAGOINHAS/BA | S33: =IF(A33=A32,0,1) -> 0 | T33: =IF(COUNTIF($B$4:B33,B33)=1,1,0) -> 0
A34: ALAGOINHAS | B34: 163 | C34: 1619 | D34: ESCOLA MUNICIPAL SANTA LUZIA | E34: POVOADO CALU | F34: POVOADO CALU - ZONA RURAL | G34: 48030-640 | H34: 1 | I34: NÃO | K34: =IF(J34="","7. Acima de 2 km",IF(J34<=50,"1. Até 50 m",IF(J34<=100,"2. De 50 a 100 m",IF(J34<=200,"3. De 100 a 200 m",IF(J34<=300,"4. De 200 a 300 m",IF(J34<=500,"5. De 300 a 500 m","6. De 500 m a 2 km")))))) -> 7. Acima de 2 km | L34: 0 | M34: 0 | N34: 0 | O34: 0 | P34: -12.162542 | Q34: -38.365642 | R34: FÓRUM DES. MOACYR PITTA LIMA, AVENIDA AIRTON SENNA, S/N, ALAGOINHAS VELHA, ALAGOINHAS/BA | S34: =IF(A34=A33,0,1) -> 0 | T34: =IF(COUNTIF($B$4:B34,B34)=1,1,0) -> 0
A35: ALAGOINHAS | B35: 163 | C35: 1627 | D35: COLÉGIO SANTÍSSIMO SACRAMENTO | E35: CENTRO | F35: RUA MARECHAL DEODORO, N 118 , CENTRO - ZONA URBANA | G35: 48000-067 | H35: 13 | I35: NÃO | J35: 133 | K35: =IF(J35="","7. Acima de 2 km",IF(J35<=50,"1. Até 50 m",IF(J35<=100,"2. De 50 a 100 m",IF(J35<=200,"3. De 100 a 200 m",IF(J35<=300,"4. De 200 a 300 m",IF(J35<=500,"5. De 300 a 500 m","6. De 500 m a 2 km")))))) -> 3. De 100 a 200 m | L35: 0 | M35: 0 | N35: 3 | O35: 4 | P35: -12.138635 | Q35: -38.420447 | R35: FÓRUM DES. MOACYR PITTA LIMA, AVENIDA AIRTON SENNA, S/N, ALAGOINHAS VELHA, ALAGOINHAS/BA | S35: =IF(A35=A34,0,1) -> 0 | T35: =IF(COUNTIF($B$4:B35,B35)=1,1,0) -> 0
A36: ALAGOINHAS | B36: 163 | C36: 1643 | D36: COLÉGIO UIRASSU DE ASSIS BATISTA | E36: SANTA TEREZINHA | F36: RUA MÁRMORE, S/N - ZONA URBANA | G36: 48020-000 | H36: 5 | I36: NÃO | J36: 264.2 | K36: =IF(J36="","7. Acima de 2 km",IF(J36<=50,"1. Até 50 m",IF(J36<=100,"2. De 50 a 100 m",IF(J36<=200,"3. De 100 a 200 m",IF(J36<=300,"4. De 200 a 300 m",IF(J36<=500,"5. De 300 a 500 m","6. De 500 m a 2 km")))))) -> 4. De 200 a 300 m | L36: 0 | M36: 0 | N36: 0 | O36: 1 | P36: -12.123152 | Q36: -38.415489 | R36: FÓRUM DES. MOACYR PITTA LIMA, AVENIDA AIRTON SENNA, S/N, ALAGOINHAS VELHA, ALAGOINHAS/BA | S36: =IF(A36=A35,0,1) -> 0 | T36: =IF(COUNTIF($B$4:B36,B36)=1,1,0) -> 0
A37: ALAGOINHAS | B37: 163 | C37: 1651 | D37: COLÉGIO MUNICIPAL DE ALAGOINHAS | E37: CENTRO | F37: PRAÇA PROF. MARIO LAERT, 421 - ZONA URBANA | G37: 48000-021 | H37: 16 | I37: NÃO | J37: 173.4 | K37: =IF(J37="","7. Acima de 2 km",IF(J37<=50,"1. Até 50 m",IF(J37<=100,"2. De 50 a 100 m",IF(J37<=200,"3. De 100 a 200 m",IF(J37<=300,"4. De 200 a 300 m",IF(J37<=500,"5. De 300 a 500 m","6. De 500 m a 2 km")))))) -> 3. De 100 a 200 m | L37: 0 | M37: 0 | N37: 1 | O37: 1 | P37: -12.139427 | Q37: -38.416266 | R37: FÓRUM DES. MOACYR PITTA LIMA, AVENIDA AIRTON SENNA, S/N, ALAGOINHAS VELHA, ALAGOINHAS/BA | S37: =IF(A37=A36,0,1) -> 0 | T37: =IF(COUNTIF($B$4:B37,B37)=1,1,0) -> 0
A38: ALAGOINHAS | B38: 163 | C38: 1660 | D38: COLÉGIO MODELO LUÍS EDUARDO MAGALHÃES | E38: CENTRO | F38: AV. LUIZ VIANA, S/N, CENTRO - ZONA URBANA | G38: 48005-420 | H38: 12 | I38: NÃO | J38: 762.3 | K38: =IF(J38="","7. Acima de 2 km",IF(J38<=50,"1. Até 50 m",IF(J38<=100,"2. De 50 a 100 m",IF(J38<=200,"3. De 100 a 200 m",IF(J38<=300,"4. De 200 a 300 m",IF(J38<=500,"5. De 300 a 500 m","6. De 500 m a 2 km")))))) -> 6. De 500 m a 2 km | L38: 0 | M38: 0 | N38: 0 | O38: 0 | P38: -12.147444 | Q38: -38.425367 | R38: FÓRUM DES. MOACYR PITTA LIMA, AVENIDA AIRTON SENNA, S/N, ALAGOINHAS VELHA, ALAGOINHAS/BA | S38: =IF(A38=A37,0,1) -> 0 | T38: =IF(COUNTIF($B$4:B38,B38)=1,1,0) -> 0
A39: ALAGOINHAS | B39: 163 | C39: 1678 | D39: ESCOLA MUNICIPAL MINISTRO MARCO MACIEL | E39: ALAGOINHAS VELHA | F39: AV. AYRTON SENNA DA SILVA, S/N - ZONA URBANA | G39: 48007-314 | H39: 4 | I39: SIM | J39: 89.3 | K39: =IF(J39="","7. Acima de 2 km",IF(J39<=50,"1. Até 50 m",IF(J39<=100,"2. De 50 a 100 m",IF(J39<=200,"3. De 100 a 200 m",IF(J39<=300,"4. De 200 a 300 m",IF(J39<=500,"5. De 300 a 500 m","6. De 500 m a 2 km")))))) -> 2. De 50 a 100 m | L39: 0 | M39: 1 | N39: 1 | O39: 1 | P39: -12.144036 | Q39: -38.403659 | R39: FÓRUM DES. MOACYR PITTA LIMA, AVENIDA AIRTON SENNA, S/N, ALAGOINHAS VELHA, ALAGOINHAS/BA | S39: =IF(A39=A38,0,1) -> 0 | T39: =IF(COUNTIF($B$4:B39,B39)=1,1,0) -> 0
A40: ALAGOINHAS | B40: 163 | C40: 1686 | D40: COLÉGIO HELENITA SANTANA DA COSTA | E40: POVOADO NARANDIBA | F40: RUA JOÃO BATISTA, S/N - ZONA RURAL | G40: 48010-700 | H40: 2 | I40: NÃO | K40: =IF(J40="","7. Acima de 2 km",IF(J40<=50,"1. Até 50 m",IF(J40<=100,"2. De 50 a 100 m",IF(J40<=200,"3. De 100 a 200 m",IF(J40<=300,"4. De 200 a 300 m",IF(J40<=500,"5. De 300 a 500 m","6. De 500 m a 2 km")))))) -> 7. Acima de 2 km | L40: 0 | M40: 0 | N40: 0 | O40: 0 | P40: -12.200193 | Q40: -38.399772 | R40: FÓRUM DES. MOACYR PITTA LIMA, AVENIDA AIRTON SENNA, S/N, ALAGOINHAS VELHA, ALAGOINHAS/BA | S40: =IF(A40=A39,0,1) -> 0 | T40: =IF(COUNTIF($B$4:B40,B40)=1,1,0) -> 0
...
